<?xml version="1.0"?>
<robot name="differential_robot">
  <link name="base_link">
    <inertial>
      <mass>10</mass>
      <inertia ixx="0.5" ixy="0" ixz="0" iyy="0.5" iyz="0" izz="1"/>
      <origin xyz="0 0 0"/>
    </inertial>
    <visual>
      <geometry>
        <box size="1 1 0.5"/>
      </geometry>
      <material name="black">
        <color rgba="0 0 0 1"/>
      </material>
      <origin xyz="0 0 0"/>
    </visual>
    <collision>
      <geometry>
        <box size="1 1 0.5"/>
      </geometry>
    </collision>
  </link>

  <joint name="wheel_joint" type="prismatic">
    <axis xyz="0 1 0"/>
    <limit effort="10" velocity="10"/>
    <dynamics damping="10" friction="10"/>
    <origin xyz="-0.5 0 0"/>
    <parent link="base_link"/>
    <child link="wheel_link"/>
  </joint>

  <link name="wheel_link">
    <inertial>
      <mass>1</mass>
      <inertia ixx="0.05" ixy="0" ixz="0" iyy="0.05" iyz="0" izz="0.01"/>
      <origin xyz="0 0 -0.2"/>
    </inertial>
    <visual>
      <geometry>
        <sphere radius="0.1"/>
      </geometry>
      <material name="black">
        <color rgba="0 0 0 1"/>
      </material>
      <origin xyz="0 0 -0.2"/>
    </visual>
    <collision>
      <geometry>
        <sphere radius="0.1"/>
      </geometry>
    </collision>
  </link>

  <joint name="other_wheel_joint" type="prismatic">
    <axis xyz="0 1 0"/>
    <limit effort="10" velocity="10"/>
    <dynamics damping="10" friction="10"/>
    <origin xyz="0.5 0 0"/>
    <parent link="base_link"/>
    <child link="wheel_link_2"/>
  </joint>

  <link name="wheel_link_2">
    <inertial>
      <mass>1</mass>
      <inertia ixx="0.05" ixy="0" ixz="0" iyy="0.05" iyz="0" izz="0.01"/>
      <origin xyz="0 0 -0.2"/>
    </inertial>
    <visual>
      <geometry>
        <sphere radius="0.1"/>
      </geometry>
      <material name="black">
        <color rgba="0 0 0 1"/>
      </material>
      <origin xyz="0 0 -0.2"/>
    </visual>
    <collision>
      <geometry>
        <sphere radius="0.1"/>
      </geometry>
    </collision>
  </link>
</robot>
