<?xml version="1.0"?>
	<robot name="raptor" xmlns:xacro="http://www.ros.org/wiki/xacro">
	<xacro:include filename="$(find raptor_v2)/robot_description/include/material.xacro"/>
	<xacro:include filename="$(find raptor_v2)/robot_description/include/gazebo.xacro"/>
	<xacro:include filename="$(find raptor_v2)/robot_description/include/_d435i.urdf.xacro"/>

  		<link name="base_link">
		</link>

		<link name="chassis_frame">
		<inertial>
      		<origin xyz="0 0 0" rpy="0 0 0"/>
      		<mass value="1.0" />
      		<inertia ixx="0.0741666666667" ixy="0.0" ixz="0.0" iyy="0.0585416666667" iyz="0.0" izz="0.0260416666667"/>
		</inertial>
			<collision>
			<geometry>
				<box size="0.80 0.54 0.22"/>
			</geometry>
			<origin rpy="0 0 0" xyz="0 0 0.10"/>
			<material name="red">
				<color rgba="1 0 0 1"/>
			</material>
			</collision>
			<visual>
			<geometry>
				<box size="0.80 0.54 0.22"/>
			</geometry>
			<origin rpy="0 0 0" xyz="0 0 0.10"/>
			<material name="red">
				<color rgba="1 0 0 1"/>
			</material>
			</visual>
		</link>
		
		<joint name="base_to_chassis_frame" type="fixed">
			<parent link="base_link"/>
			<child link="chassis_frame"/>
			<origin xyz="0 0 0.10" rpy="0 0 0"/>
		</joint>
	
			<!-- caster -->
		<link name="caster_wheel">
			<inertial>
    	  		<origin xyz="0 0 0" rpy="0 0 0"/>
    	  		<mass value="1.0" />
    	  		<inertia ixx="0.0741666666667" ixy="0.0" ixz="0.0" iyy="0.0585416666667" iyz="0.0" izz="0.0260416666667"/>
			</inertial>
			<collision name="caster_rear_collision">
    			<origin rpy=" 0 0 0" xyz="0 0 0"/>
    			<geometry>
      				<sphere radius="0.11"/>
    			</geometry>
    			<surface>
      				<friction>
        				<ode>
          					<mu>0</mu>
          					<mu2>0</mu2>
          					<slip1>1.0</slip1>
          					<slip2>1.0</slip2>
        				</ode>
      				</friction>
    			</surface>
  			</collision>
  			<visual>
    			<origin rpy=" 0 0 0" xyz="0 0 0"/>
    			<geometry>
      				<sphere radius="0.11"/>
    			</geometry>
				<material name="black">
					<color rgba="0.0 0.0 0.0 1.0"/>
				</material>
  			</visual>
		</link>

		<joint name="caster_to_chassis_frame" type="fixed">
			<parent link="chassis_frame"/>
			<child link="caster_wheel"/>
			<origin rpy=" 0 0 0" xyz="-0.38 0 0.01"/>
		</joint>

<!--
		<link name="imu_link">
		</link> 

		<joint name="imu_joint" type="fixed">
			<origin xyz="0.35 0.02 0.39" rpy="0 0 0" />
			<parent link="base_link" />
			<child link="imu_link" />
		</joint>
-->

		<link name="lwheel">
			<inertial>
      			<origin xyz="0 0 0" rpy="0 0 0"/>
      			<mass value="1.0" />
      			<inertia ixx="0.0741666666667" ixy="0.0" ixz="0.0" iyy="0.0585416666667" iyz="0.0" izz="0.0260416666667"/>
			</inertial>
			<collision name="lwheel_collision">
    			<origin rpy=" 0 0 0" xyz="0 0 0"/>
    			<geometry>
      				<cylinder length="0.07" radius="0.14"/>
    			</geometry>
  			</collision>
			<visual>
			<geometry>
				<cylinder length="0.07" radius="0.14"/>
			</geometry>
			<origin rpy="0 0 0" xyz="0 0 0"/>
			<material name="black">
				<color rgba="0 0 0 1"/>
			</material>
			</visual>
  		</link>
 
		<joint name="base_to_lwheel" type="continuous">
			<parent link="base_link"/>
			<child link="lwheel"/>
			<origin xyz="0.13 0.21 0.14" rpy="1.5708 0 0"/>
			<axis xyz="0.0 0.0 -1.0"/>
		</joint>
		
		<link name="rwheel">
			<inertial>
      			<origin xyz="0 0 0" rpy="0 0 0"/>
      			<mass value="1.0" />
      			<inertia ixx="0.0741666666667" ixy="0.0" ixz="0.0" iyy="0.0585416666667" iyz="0.0" izz="0.0260416666667"/>
			</inertial>
			<collision name="rwheel_collision">
    			<origin rpy=" 0 0 0" xyz="0 0 0"/>
    			<geometry>
      				<cylinder length="0.07" radius="0.14"/>
    			</geometry>
  			</collision>
			<visual>
			<geometry>
				<cylinder length="0.07" radius="0.14"/>
			</geometry>
			<origin rpy="0 0 0" xyz="0 0 0"/>
			<material name="black">
				<color rgba="0 0 0 1"/>
			</material>
			</visual>
		</link>
		
		<joint name="base_to_rwheel" type="continuous">
			<parent link="base_link"/>
			<child link="rwheel"/>
			<origin xyz="0.13 -0.21 0.14" rpy="-1.5708 0 0"/>
			<axis xyz="0.0 0.0 1.0"/>
		</joint>

		<link name="laser">
			<inertial>
      			<origin xyz="0 0 0" rpy="0 0 0"/>
      			<mass value="1.0" />
      			<inertia ixx="0.0741666666667" ixy="0.0" ixz="0.0" iyy="0.0585416666667" iyz="0.0" izz="0.0260416666667"/>
			</inertial>
			<visual>
			<geometry>
				<cylinder length="0.04" radius="0.03"/>
			</geometry>
			<origin rpy="0 0 0" xyz="0 0 0"/>
			<material name="black">
				<color rgba="0 0 0 1"/>
			</material>
			</visual>

			<collision>
				<origin xyz="0 0 0" rpy="0 0 0"/>
				<geometry>
					<cylinder length="0.04" radius="0.03"/>
				</geometry>
			</collision>
		</link>

		<joint name="base_link_to_front_laser" type="fixed">
			<parent link="base_link"/>
			<child link="laser"/>
			<!--
			<origin xyz="0.163 0 0.3" rpy="0.0 0.0 3.141592"/>
			-->
			<origin xyz="0.35 0.0 0.35" rpy="0.0 0.0 0.0"/>

			<axis xyz="0 0 0"/>
		</joint>


		<!-- Camera 
		<link name="camera_link">
			<inertial>
      			<origin xyz="0 0 0" rpy="0 0 0"/>
      			<mass value="1.0" />
      			<inertia ixx="0.0741666666667" ixy="0.0" ixz="0.0" iyy="0.0585416666667" iyz="0.0" izz="0.0260416666667"/>
			</inertial>

			<visual>
				<origin xyz="0 0 0" rpy="0 0 0"/>
				<geometry>
					<box size="0.015 0.05 0.015"/>
				</geometry>
				<material name="black">
					<color rgba="0 0 0 1"/>
				</material>
			</visual>

			<collision>
				<origin xyz="0 0 0" rpy="0 0 0"/>
				<geometry>
					<box size="0.015 0.05 0.015"/>
				</geometry>
			</collision>
		</link>
-->
		<!-- Camera Joint 
		<joint name="camera_joint" type="fixed">
			<origin xyz="-0.16 0 0.93" rpy="0 0 0" />
			<parent link="base_link"/>
			<child link="camera_link" />
			<axis xyz="0 0 0"/>
		</joint>
-->
		<xacro:sensor_d435i parent="base_link">
			
		</xacro:sensor_d435i>

	</robot>